<?xml version="1.0" ?>
<!-- Generated using onshape-to-robot -->
<!-- Modified: removed link_6 and joint6 -->
<robot name="yam_v0_no_gripper">
  <link name="base_link">
    <visual>
      <origin xyz="-7.22812e-05 2.52572e-05 0.0159932" rpy="0 0 0"/>
      <geometry><mesh filename="package://assets/base_link_visual.stl"/></geometry>
      <material name="orange"><color rgba="1 0.6 0 1.0"/></material>
    </visual>
  </link>
  <link name="link_1">
    <visual>
      <origin xyz="-0.00192861 -0.00795735 0.0208176" rpy="0 0 -1.5708"/>
      <geometry><mesh filename="package://assets/link_1_visual.stl"/></geometry>
      <material name="orange"><color rgba="1 0.6 0 1.0"/></material>
    </visual>
  </link>
  <link name="link_2">
    <visual>
      <origin xyz="0.132008 2.10599e-06 0.000293073" rpy="1.5708 0 3.14159"/>
      <geometry><mesh filename="package://assets/link_2_visual.stl"/></geometry>
      <material name="orange"><color rgba="1 0.6 0 1.0"/></material>
    </visual>
  </link>
  <link name="link_3">
    <visual>
      <origin xyz="-0.121816 -0.054846 -0.000111108" rpy="-1.5708 0 -3.14159"/>
      <geometry><mesh filename="package://assets/link_3_visual.stl"/></geometry>
      <material name="orange"><color rgba="1 0.6 0 1.0"/></material>
    </visual>
  </link>
  <link name="link_4">
    <visual>
      <origin xyz="-0.0569778 -0.0527104 0.000154878" rpy="-1.5708 0 -3.14159"/>
      <geometry><mesh filename="package://assets/link_4_visual.stl"/></geometry>
      <material name="orange"><color rgba="1 0.6 0 1.0"/></material>
    </visual>
  </link>
  <link name="link_5">
    <visual>
      <origin xyz="3.64861e-05 0.00025665 0.0353526" rpy="-3.14159 0 1.5708"/>
      <geometry><mesh filename="package://assets/link_5_visual.stl"/></geometry>
      <material name="orange"><color rgba="1 0.6 0 1.0"/></material>
    </visual>
  </link>
  <joint name="joint1" type="revolute">
    <origin xyz="0 0 0.0631" rpy="0 0 1.5708"/>
    <parent link="base_link"/><child link="link_1"/>
    <axis xyz="0 0 1"/>
    <limit effort="10" velocity="10" lower="-2.61799" upper="3.05433"/>
  </joint>
  <joint name="joint2" type="revolute">
    <origin xyz="2.5e-05 -0.02 0.0409" rpy="1.5708 0 1.5708"/>
    <parent link="link_1"/><child link="link_2"/>
    <axis xyz="0 0 1"/>
    <limit effort="10" velocity="10" lower="-0.1" upper="3.66"/>
  </joint>
  <joint name="joint3" type="revolute">
    <origin xyz="0.264 0 0" rpy="-3.14159 0 0"/>
    <parent link="link_2"/><child link="link_3"/>
    <axis xyz="0 0 1"/>
    <limit effort="10" velocity="10" lower="0" upper="3.66519"/>
  </joint>
  <joint name="joint4" type="revolute">
    <origin xyz="-0.245 -0.0600003 0" rpy="0 0 0"/>
    <parent link="link_3"/><child link="link_4"/>
    <axis xyz="0 0 1"/>
    <limit effort="10" velocity="10" lower="-1.5708" upper="1.5708"/>
  </joint>
  <joint name="joint5" type="revolute">
    <origin xyz="-0.0739968 -0.0395003 2.44738e-05" rpy="-1.5708 1.5708 0"/>
    <parent link="link_4"/><child link="link_5"/>
    <axis xyz="0 0 1"/>
    <limit effort="10" velocity="10" lower="-1.5708" upper="1.5708"/>
  </joint>
</robot>
