<?xml version="1.0" encoding="utf-8"?>
<robot name="big-yam-dual">

  <!-- World base -->
  <link name="world"/>

  <!-- ==================== LEFT ARM ==================== -->
  <link name="left_base_link">
    <visual>
      <origin xyz="0 0 0" rpy="0 0 -1.5708"/>
      <geometry><mesh filename="assets/joint1.STL"/></geometry>
      <material name="silver"><color rgba="0.75 0.75 0.75 1"/></material>
    </visual>
  </link>
  <joint name="left_base_joint" type="fixed">
    <origin xyz="0 0.25 0" rpy="0 0 0"/>
    <parent link="world"/>
    <child link="left_base_link"/>
  </joint>

  <link name="left_link_1">
    <visual>
      <origin xyz="0 0 0" rpy="0 0 0"/>
      <geometry><mesh filename="assets/joint2_link.STL"/></geometry>
      <material name="silver"><color rgba="0.75 0.75 0.75 1"/></material>
    </visual>
  </link>
  <joint name="left_joint1" type="revolute">
    <origin xyz="0 0 0.07735" rpy="0 0 -1.5708"/>
    <parent link="left_base_link"/><child link="left_link_1"/>
    <axis xyz="0 0 1"/>
    <limit effort="10" velocity="10" lower="-2.61799" upper="3.05433"/>
  </joint>

  <link name="left_link_2">
    <visual>
      <origin xyz="0 0 0" rpy="0 0 0"/>
      <geometry><mesh filename="assets/joint3_link.STL"/></geometry>
      <material name="silver"><color rgba="0.75 0.75 0.75 1"/></material>
    </visual>
  </link>
  <joint name="left_joint2" type="revolute">
    <origin xyz="0 0.021912 0.053202" rpy="0 0 0"/>
    <parent link="left_link_1"/><child link="left_link_2"/>
    <axis xyz="1 0 0"/>
    <limit effort="10" velocity="10" lower="-3.66" upper="0.1"/>
  </joint>

  <link name="left_link_3">
    <visual>
      <origin xyz="0 0 0" rpy="0 0 0"/>
      <geometry><mesh filename="assets/joint4_link.STL"/></geometry>
      <material name="silver"><color rgba="0.75 0.75 0.75 1"/></material>
    </visual>
  </link>
  <joint name="left_joint3" type="revolute">
    <origin xyz="0 -0.3787 0.068" rpy="0 0 0"/>
    <parent link="left_link_2"/><child link="left_link_3"/>
    <axis xyz="1 0 0"/>
    <limit effort="10" velocity="10" lower="-0.1" upper="3.66519"/>
  </joint>

  <link name="left_link_4">
    <visual>
      <origin xyz="0 0 0" rpy="0 0 0"/>
      <geometry><mesh filename="assets/joint5_link.STL"/></geometry>
      <material name="silver"><color rgba="0.75 0.75 0.75 1"/></material>
    </visual>
  </link>
  <joint name="left_joint4" type="revolute">
    <origin xyz="0 0.38198 0" rpy="0 0 0"/>
    <parent link="left_link_3"/><child link="left_link_4"/>
    <axis xyz="1 0 0"/>
    <limit effort="10" velocity="10" lower="-1.5708" upper="1.5708"/>
  </joint>

  <link name="left_link_5">
    <visual>
      <origin xyz="0 0 0" rpy="0 0 0"/>
      <geometry><mesh filename="assets/joint6_link.STL"/></geometry>
      <material name="silver"><color rgba="0.75 0.75 0.75 1"/></material>
    </visual>
  </link>
  <joint name="left_joint5" type="revolute">
    <origin xyz="0 0.074 0.0455" rpy="0 0 0"/>
    <parent link="left_link_4"/><child link="left_link_5"/>
    <axis xyz="0 0 -1"/>
    <limit effort="10" velocity="10" lower="-1.5708" upper="1.5708"/>
  </joint>

  <link name="left_link_6"/>
  <joint name="left_joint6" type="revolute">
    <origin xyz="0 0.0235 -0.0455" rpy="0 0 0"/>
    <parent link="left_link_5"/><child link="left_link_6"/>
    <axis xyz="0 1 0"/>
    <limit effort="10" velocity="10" lower="-3.14" upper="3.14"/>
  </joint>

  <!-- Left gripper fingers -->
  <link name="left_finger_l">
    <visual>
      <origin xyz="0 0 0" rpy="0 0 0"/>
      <geometry><mesh filename="assets/finger-l-link.STL"/></geometry>
      <material name="silver"><color rgba="0.75 0.75 0.75 1"/></material>
    </visual>
  </link>
  <joint name="left_gripper_l" type="prismatic">
    <origin xyz="0 0.005 0" rpy="0 0 0"/>
    <parent link="left_link_6"/><child link="left_finger_l"/>
    <axis xyz="-1 0 0"/>
    <limit effort="10" velocity="10" lower="0" upper="0.095"/>
  </joint>

  <link name="left_finger_r">
    <visual>
      <origin xyz="0 0 0" rpy="0 0 0"/>
      <geometry><mesh filename="assets/finger-r-link.STL"/></geometry>
      <material name="silver"><color rgba="0.75 0.75 0.75 1"/></material>
    </visual>
  </link>
  <joint name="left_gripper_r" type="prismatic">
    <origin xyz="0 0.005 0" rpy="0 0 0"/>
    <parent link="left_link_6"/><child link="left_finger_r"/>
    <axis xyz="1 0 0"/>
    <limit effort="10" velocity="10" lower="0" upper="0.095"/>
  </joint>

  <link name="left_eef_link"/>
  <joint name="left_eef_joint" type="fixed">
    <origin xyz="0 0 0" rpy="1.5708 0 3.14159"/>
    <parent link="left_link_6"/><child link="left_eef_link"/>
  </joint>

  <!-- ==================== RIGHT ARM ==================== -->
  <link name="right_base_link">
    <visual>
      <origin xyz="0 0 0" rpy="0 0 -1.5708"/>
      <geometry><mesh filename="assets/joint1.STL"/></geometry>
      <material name="blue"><color rgba="0.3 0.5 0.9 1"/></material>
    </visual>
  </link>
  <joint name="right_base_joint" type="fixed">
    <origin xyz="0 -0.25 0" rpy="0 0 0"/>
    <parent link="world"/>
    <child link="right_base_link"/>
  </joint>

  <link name="right_link_1">
    <visual>
      <origin xyz="0 0 0" rpy="0 0 0"/>
      <geometry><mesh filename="assets/joint2_link.STL"/></geometry>
      <material name="blue"><color rgba="0.3 0.5 0.9 1"/></material>
    </visual>
  </link>
  <joint name="right_joint1" type="revolute">
    <origin xyz="0 0 0.07735" rpy="0 0 -1.5708"/>
    <parent link="right_base_link"/><child link="right_link_1"/>
    <axis xyz="0 0 1"/>
    <limit effort="10" velocity="10" lower="-2.61799" upper="3.05433"/>
  </joint>

  <link name="right_link_2">
    <visual>
      <origin xyz="0 0 0" rpy="0 0 0"/>
      <geometry><mesh filename="assets/joint3_link.STL"/></geometry>
      <material name="blue"><color rgba="0.3 0.5 0.9 1"/></material>
    </visual>
  </link>
  <joint name="right_joint2" type="revolute">
    <origin xyz="0 0.021912 0.053202" rpy="0 0 0"/>
    <parent link="right_link_1"/><child link="right_link_2"/>
    <axis xyz="1 0 0"/>
    <limit effort="10" velocity="10" lower="-3.66" upper="0.1"/>
  </joint>

  <link name="right_link_3">
    <visual>
      <origin xyz="0 0 0" rpy="0 0 0"/>
      <geometry><mesh filename="assets/joint4_link.STL"/></geometry>
      <material name="blue"><color rgba="0.3 0.5 0.9 1"/></material>
    </visual>
  </link>
  <joint name="right_joint3" type="revolute">
    <origin xyz="0 -0.3787 0.068" rpy="0 0 0"/>
    <parent link="right_link_2"/><child link="right_link_3"/>
    <axis xyz="1 0 0"/>
    <limit effort="10" velocity="10" lower="-0.1" upper="3.66519"/>
  </joint>

  <link name="right_link_4">
    <visual>
      <origin xyz="0 0 0" rpy="0 0 0"/>
      <geometry><mesh filename="assets/joint5_link.STL"/></geometry>
      <material name="blue"><color rgba="0.3 0.5 0.9 1"/></material>
    </visual>
  </link>
  <joint name="right_joint4" type="revolute">
    <origin xyz="0 0.38198 0" rpy="0 0 0"/>
    <parent link="right_link_3"/><child link="right_link_4"/>
    <axis xyz="1 0 0"/>
    <limit effort="10" velocity="10" lower="-1.5708" upper="1.5708"/>
  </joint>

  <link name="right_link_5">
    <visual>
      <origin xyz="0 0 0" rpy="0 0 0"/>
      <geometry><mesh filename="assets/joint6_link.STL"/></geometry>
      <material name="blue"><color rgba="0.3 0.5 0.9 1"/></material>
    </visual>
  </link>
  <joint name="right_joint5" type="revolute">
    <origin xyz="0 0.074 0.0455" rpy="0 0 0"/>
    <parent link="right_link_4"/><child link="right_link_5"/>
    <axis xyz="0 0 -1"/>
    <limit effort="10" velocity="10" lower="-1.5708" upper="1.5708"/>
  </joint>

  <link name="right_link_6"/>
  <joint name="right_joint6" type="revolute">
    <origin xyz="0 0.0235 -0.0455" rpy="0 0 0"/>
    <parent link="right_link_5"/><child link="right_link_6"/>
    <axis xyz="0 1 0"/>
    <limit effort="10" velocity="10" lower="-3.14" upper="3.14"/>
  </joint>

  <!-- Right gripper fingers -->
  <link name="right_finger_l">
    <visual>
      <origin xyz="0 0 0" rpy="0 0 0"/>
      <geometry><mesh filename="assets/finger-l-link.STL"/></geometry>
      <material name="blue"><color rgba="0.3 0.5 0.9 1"/></material>
    </visual>
  </link>
  <joint name="right_gripper_l" type="prismatic">
    <origin xyz="0 0.005 0" rpy="0 0 0"/>
    <parent link="right_link_6"/><child link="right_finger_l"/>
    <axis xyz="-1 0 0"/>
    <limit effort="10" velocity="10" lower="0" upper="0.095"/>
  </joint>

  <link name="right_finger_r">
    <visual>
      <origin xyz="0 0 0" rpy="0 0 0"/>
      <geometry><mesh filename="assets/finger-r-link.STL"/></geometry>
      <material name="blue"><color rgba="0.3 0.5 0.9 1"/></material>
    </visual>
  </link>
  <joint name="right_gripper_r" type="prismatic">
    <origin xyz="0 0.005 0" rpy="0 0 0"/>
    <parent link="right_link_6"/><child link="right_finger_r"/>
    <axis xyz="1 0 0"/>
    <limit effort="10" velocity="10" lower="0" upper="0.095"/>
  </joint>

  <link name="right_eef_link"/>
  <joint name="right_eef_joint" type="fixed">
    <origin xyz="0 0 0" rpy="1.5708 0 3.14159"/>
    <parent link="right_link_6"/><child link="right_eef_link"/>
  </joint>

</robot>
